[92m20:41:02 - LiteLLM:ERROR[0m: caching.py:563 - LiteLLM Cache: Excepton add_cache: __annotations__
Traceback (most recent call last):
  File "C:\Users\PC\AppData\Roaming\Python\Python312\site-packages\litellm\caching\caching.py", line 558, in add_cache
    cache_key, cached_data, kwargs = self._add_cache_logic(
                                     ^^^^^^^^^^^^^^^^^^^^^^
  File "C:\Users\PC\AppData\Roaming\Python\Python312\site-packages\litellm\caching\caching.py", line 542, in _add_cache_logic
    raise e
  File "C:\Users\PC\AppData\Roaming\Python\Python312\site-packages\litellm\caching\caching.py", line 522, in _add_cache_logic
    cache_key = self.get_cache_key(**kwargs)
                ^^^^^^^^^^^^^^^^^^^^^^^^^^^^
  File "C:\Users\PC\AppData\Roaming\Python\Python312\site-packages\litellm\caching\caching.py", line 248, in get_cache_key
    combined_kwargs = ModelParamHelper._get_all_llm_api_params()
                      ^^^^^^^^^^^^^^^^^^^^^^^^^^^^^^^^^^^^^^^^^^
  File "C:\Users\PC\AppData\Roaming\Python\Python312\site-packages\litellm\litellm_core_utils\model_param_helper.py", line 65, in _get_all_llm_api_params
    ModelParamHelper._get_litellm_supported_transcription_kwargs()
  File "C:\Users\PC\AppData\Roaming\Python\Python312\site-packages\litellm\litellm_core_utils\model_param_helper.py", line 126, in _get_litellm_supported_transcription_kwargs
    return set(TranscriptionCreateParams.__annotations__.keys())
               ^^^^^^^^^^^^^^^^^^^^^^^^^^^^^^^^^^^^^^^^^
  File "C:\Python312\Lib\typing.py", line 1213, in __getattr__
    raise AttributeError(attr)
AttributeError: __annotations__
[92m20:41:02 - LiteLLM:ERROR[0m: litellm_logging.py:3482 - Error creating standard logging object - __annotations__
Traceback (most recent call last):
  File "C:\Users\PC\AppData\Roaming\Python\Python312\site-packages\litellm\litellm_core_utils\litellm_logging.py", line 3464, in get_standard_logging_object_payload
    model_parameters=ModelParamHelper.get_standard_logging_model_parameters(
                     ^^^^^^^^^^^^^^^^^^^^^^^^^^^^^^^^^^^^^^^^^^^^^^^^^^^^^^^
  File "C:\Users\PC\AppData\Roaming\Python\Python312\site-packages\litellm\litellm_core_utils\model_param_helper.py", line 28, in get_standard_logging_model_parameters
    ModelParamHelper._get_relevant_args_to_use_for_logging()
  File "C:\Users\PC\AppData\Roaming\Python\Python312\site-packages\litellm\litellm_core_utils\model_param_helper.py", line 45, in _get_relevant_args_to_use_for_logging
    all_openai_llm_api_params = ModelParamHelper._get_all_llm_api_params()
                                ^^^^^^^^^^^^^^^^^^^^^^^^^^^^^^^^^^^^^^^^^^
  File "C:\Users\PC\AppData\Roaming\Python\Python312\site-packages\litellm\litellm_core_utils\model_param_helper.py", line 65, in _get_all_llm_api_params
    ModelParamHelper._get_litellm_supported_transcription_kwargs()
  File "C:\Users\PC\AppData\Roaming\Python\Python312\site-packages\litellm\litellm_core_utils\model_param_helper.py", line 126, in _get_litellm_supported_transcription_kwargs
    return set(TranscriptionCreateParams.__annotations__.keys())
               ^^^^^^^^^^^^^^^^^^^^^^^^^^^^^^^^^^^^^^^^^
  File "C:\Python312\Lib\typing.py", line 1213, in __getattr__
    raise AttributeError(attr)
AttributeError: __annotations__
[92m20:41:02 - LiteLLM:ERROR[0m: litellm_logging.py:3482 - Error creating standard logging object - __annotations__
Traceback (most recent call last):
  File "C:\Users\PC\AppData\Roaming\Python\Python312\site-packages\litellm\litellm_core_utils\litellm_logging.py", line 3464, in get_standard_logging_object_payload
    model_parameters=ModelParamHelper.get_standard_logging_model_parameters(
                     ^^^^^^^^^^^^^^^^^^^^^^^^^^^^^^^^^^^^^^^^^^^^^^^^^^^^^^^
  File "C:\Users\PC\AppData\Roaming\Python\Python312\site-packages\litellm\litellm_core_utils\model_param_helper.py", line 28, in get_standard_logging_model_parameters
    ModelParamHelper._get_relevant_args_to_use_for_logging()
  File "C:\Users\PC\AppData\Roaming\Python\Python312\site-packages\litellm\litellm_core_utils\model_param_helper.py", line 45, in _get_relevant_args_to_use_for_logging
    all_openai_llm_api_params = ModelParamHelper._get_all_llm_api_params()
                                ^^^^^^^^^^^^^^^^^^^^^^^^^^^^^^^^^^^^^^^^^^
  File "C:\Users\PC\AppData\Roaming\Python\Python312\site-packages\litellm\litellm_core_utils\model_param_helper.py", line 65, in _get_all_llm_api_params
    ModelParamHelper._get_litellm_supported_transcription_kwargs()
  File "C:\Users\PC\AppData\Roaming\Python\Python312\site-packages\litellm\litellm_core_utils\model_param_helper.py", line 126, in _get_litellm_supported_transcription_kwargs
    return set(TranscriptionCreateParams.__annotations__.keys())
               ^^^^^^^^^^^^^^^^^^^^^^^^^^^^^^^^^^^^^^^^^
  File "C:\Python312\Lib\typing.py", line 1213, in __getattr__
    raise AttributeError(attr)
AttributeError: __annotations__
[92m20:41:07 - LiteLLM:ERROR[0m: caching.py:563 - LiteLLM Cache: Excepton add_cache: __annotations__
Traceback (most recent call last):
  File "C:\Users\PC\AppData\Roaming\Python\Python312\site-packages\litellm\caching\caching.py", line 558, in add_cache
    cache_key, cached_data, kwargs = self._add_cache_logic(
                                     ^^^^^^^^^^^^^^^^^^^^^^
  File "C:\Users\PC\AppData\Roaming\Python\Python312\site-packages\litellm\caching\caching.py", line 542, in _add_cache_logic
    raise e
  File "C:\Users\PC\AppData\Roaming\Python\Python312\site-packages\litellm\caching\caching.py", line 522, in _add_cache_logic
    cache_key = self.get_cache_key(**kwargs)
                ^^^^^^^^^^^^^^^^^^^^^^^^^^^^
  File "C:\Users\PC\AppData\Roaming\Python\Python312\site-packages\litellm\caching\caching.py", line 248, in get_cache_key
    combined_kwargs = ModelParamHelper._get_all_llm_api_params()
                      ^^^^^^^^^^^^^^^^^^^^^^^^^^^^^^^^^^^^^^^^^^
  File "C:\Users\PC\AppData\Roaming\Python\Python312\site-packages\litellm\litellm_core_utils\model_param_helper.py", line 65, in _get_all_llm_api_params
    ModelParamHelper._get_litellm_supported_transcription_kwargs()
  File "C:\Users\PC\AppData\Roaming\Python\Python312\site-packages\litellm\litellm_core_utils\model_param_helper.py", line 126, in _get_litellm_supported_transcription_kwargs
    return set(TranscriptionCreateParams.__annotations__.keys())
               ^^^^^^^^^^^^^^^^^^^^^^^^^^^^^^^^^^^^^^^^^
  File "C:\Python312\Lib\typing.py", line 1213, in __getattr__
    raise AttributeError(attr)
AttributeError: __annotations__
[92m20:41:07 - LiteLLM:ERROR[0m: litellm_logging.py:3482 - Error creating standard logging object - __annotations__
Traceback (most recent call last):
  File "C:\Users\PC\AppData\Roaming\Python\Python312\site-packages\litellm\litellm_core_utils\litellm_logging.py", line 3464, in get_standard_logging_object_payload
    model_parameters=ModelParamHelper.get_standard_logging_model_parameters(
                     ^^^^^^^^^^^^^^^^^^^^^^^^^^^^^^^^^^^^^^^^^^^^^^^^^^^^^^^
  File "C:\Users\PC\AppData\Roaming\Python\Python312\site-packages\litellm\litellm_core_utils\model_param_helper.py", line 28, in get_standard_logging_model_parameters
    ModelParamHelper._get_relevant_args_to_use_for_logging()
  File "C:\Users\PC\AppData\Roaming\Python\Python312\site-packages\litellm\litellm_core_utils\model_param_helper.py", line 45, in _get_relevant_args_to_use_for_logging
    all_openai_llm_api_params = ModelParamHelper._get_all_llm_api_params()
                                ^^^^^^^^^^^^^^^^^^^^^^^^^^^^^^^^^^^^^^^^^^
  File "C:\Users\PC\AppData\Roaming\Python\Python312\site-packages\litellm\litellm_core_utils\model_param_helper.py", line 65, in _get_all_llm_api_params
    ModelParamHelper._get_litellm_supported_transcription_kwargs()
  File "C:\Users\PC\AppData\Roaming\Python\Python312\site-packages\litellm\litellm_core_utils\model_param_helper.py", line 126, in _get_litellm_supported_transcription_kwargs
    return set(TranscriptionCreateParams.__annotations__.keys())
               ^^^^^^^^^^^^^^^^^^^^^^^^^^^^^^^^^^^^^^^^^
  File "C:\Python312\Lib\typing.py", line 1213, in __getattr__
    raise AttributeError(attr)
AttributeError: __annotations__
[92m20:41:07 - LiteLLM:ERROR[0m: litellm_logging.py:3482 - Error creating standard logging object - __annotations__
Traceback (most recent call last):
  File "C:\Users\PC\AppData\Roaming\Python\Python312\site-packages\litellm\litellm_core_utils\litellm_logging.py", line 3464, in get_standard_logging_object_payload
    model_parameters=ModelParamHelper.get_standard_logging_model_parameters(
                     ^^^^^^^^^^^^^^^^^^^^^^^^^^^^^^^^^^^^^^^^^^^^^^^^^^^^^^^
  File "C:\Users\PC\AppData\Roaming\Python\Python312\site-packages\litellm\litellm_core_utils\model_param_helper.py", line 28, in get_standard_logging_model_parameters
    ModelParamHelper._get_relevant_args_to_use_for_logging()
  File "C:\Users\PC\AppData\Roaming\Python\Python312\site-packages\litellm\litellm_core_utils\model_param_helper.py", line 45, in _get_relevant_args_to_use_for_logging
    all_openai_llm_api_params = ModelParamHelper._get_all_llm_api_params()
                                ^^^^^^^^^^^^^^^^^^^^^^^^^^^^^^^^^^^^^^^^^^
  File "C:\Users\PC\AppData\Roaming\Python\Python312\site-packages\litellm\litellm_core_utils\model_param_helper.py", line 65, in _get_all_llm_api_params
    ModelParamHelper._get_litellm_supported_transcription_kwargs()
  File "C:\Users\PC\AppData\Roaming\Python\Python312\site-packages\litellm\litellm_core_utils\model_param_helper.py", line 126, in _get_litellm_supported_transcription_kwargs
    return set(TranscriptionCreateParams.__annotations__.keys())
               ^^^^^^^^^^^^^^^^^^^^^^^^^^^^^^^^^^^^^^^^^
  File "C:\Python312\Lib\typing.py", line 1213, in __getattr__
    raise AttributeError(attr)
AttributeError: __annotations__
[92m20:41:12 - LiteLLM:ERROR[0m: caching.py:563 - LiteLLM Cache: Excepton add_cache: __annotations__
Traceback (most recent call last):
  File "C:\Users\PC\AppData\Roaming\Python\Python312\site-packages\litellm\caching\caching.py", line 558, in add_cache
    cache_key, cached_data, kwargs = self._add_cache_logic(
                                     ^^^^^^^^^^^^^^^^^^^^^^
  File "C:\Users\PC\AppData\Roaming\Python\Python312\site-packages\litellm\caching\caching.py", line 542, in _add_cache_logic
    raise e
  File "C:\Users\PC\AppData\Roaming\Python\Python312\site-packages\litellm\caching\caching.py", line 522, in _add_cache_logic
    cache_key = self.get_cache_key(**kwargs)
                ^^^^^^^^^^^^^^^^^^^^^^^^^^^^
  File "C:\Users\PC\AppData\Roaming\Python\Python312\site-packages\litellm\caching\caching.py", line 248, in get_cache_key
    combined_kwargs = ModelParamHelper._get_all_llm_api_params()
                      ^^^^^^^^^^^^^^^^^^^^^^^^^^^^^^^^^^^^^^^^^^
  File "C:\Users\PC\AppData\Roaming\Python\Python312\site-packages\litellm\litellm_core_utils\model_param_helper.py", line 65, in _get_all_llm_api_params
    ModelParamHelper._get_litellm_supported_transcription_kwargs()
  File "C:\Users\PC\AppData\Roaming\Python\Python312\site-packages\litellm\litellm_core_utils\model_param_helper.py", line 126, in _get_litellm_supported_transcription_kwargs
    return set(TranscriptionCreateParams.__annotations__.keys())
               ^^^^^^^^^^^^^^^^^^^^^^^^^^^^^^^^^^^^^^^^^
  File "C:\Python312\Lib\typing.py", line 1213, in __getattr__
    raise AttributeError(attr)
AttributeError: __annotations__
[92m20:41:12 - LiteLLM:ERROR[0m: litellm_logging.py:3482 - Error creating standard logging object - __annotations__
Traceback (most recent call last):
  File "C:\Users\PC\AppData\Roaming\Python\Python312\site-packages\litellm\litellm_core_utils\litellm_logging.py", line 3464, in get_standard_logging_object_payload
    model_parameters=ModelParamHelper.get_standard_logging_model_parameters(
                     ^^^^^^^^^^^^^^^^^^^^^^^^^^^^^^^^^^^^^^^^^^^^^^^^^^^^^^^
  File "C:\Users\PC\AppData\Roaming\Python\Python312\site-packages\litellm\litellm_core_utils\model_param_helper.py", line 28, in get_standard_logging_model_parameters
    ModelParamHelper._get_relevant_args_to_use_for_logging()
  File "C:\Users\PC\AppData\Roaming\Python\Python312\site-packages\litellm\litellm_core_utils\model_param_helper.py", line 45, in _get_relevant_args_to_use_for_logging
    all_openai_llm_api_params = ModelParamHelper._get_all_llm_api_params()
                                ^^^^^^^^^^^^^^^^^^^^^^^^^^^^^^^^^^^^^^^^^^
  File "C:\Users\PC\AppData\Roaming\Python\Python312\site-packages\litellm\litellm_core_utils\model_param_helper.py", line 65, in _get_all_llm_api_params
    ModelParamHelper._get_litellm_supported_transcription_kwargs()
  File "C:\Users\PC\AppData\Roaming\Python\Python312\site-packages\litellm\litellm_core_utils\model_param_helper.py", line 126, in _get_litellm_supported_transcription_kwargs
    return set(TranscriptionCreateParams.__annotations__.keys())
               ^^^^^^^^^^^^^^^^^^^^^^^^^^^^^^^^^^^^^^^^^
  File "C:\Python312\Lib\typing.py", line 1213, in __getattr__
    raise AttributeError(attr)
AttributeError: __annotations__
[92m20:41:12 - LiteLLM:ERROR[0m: litellm_logging.py:3482 - Error creating standard logging object - __annotations__
Traceback (most recent call last):
  File "C:\Users\PC\AppData\Roaming\Python\Python312\site-packages\litellm\litellm_core_utils\litellm_logging.py", line 3464, in get_standard_logging_object_payload
    model_parameters=ModelParamHelper.get_standard_logging_model_parameters(
                     ^^^^^^^^^^^^^^^^^^^^^^^^^^^^^^^^^^^^^^^^^^^^^^^^^^^^^^^
  File "C:\Users\PC\AppData\Roaming\Python\Python312\site-packages\litellm\litellm_core_utils\model_param_helper.py", line 28, in get_standard_logging_model_parameters
    ModelParamHelper._get_relevant_args_to_use_for_logging()
  File "C:\Users\PC\AppData\Roaming\Python\Python312\site-packages\litellm\litellm_core_utils\model_param_helper.py", line 45, in _get_relevant_args_to_use_for_logging
    all_openai_llm_api_params = ModelParamHelper._get_all_llm_api_params()
                                ^^^^^^^^^^^^^^^^^^^^^^^^^^^^^^^^^^^^^^^^^^
  File "C:\Users\PC\AppData\Roaming\Python\Python312\site-packages\litellm\litellm_core_utils\model_param_helper.py", line 65, in _get_all_llm_api_params
    ModelParamHelper._get_litellm_supported_transcription_kwargs()
  File "C:\Users\PC\AppData\Roaming\Python\Python312\site-packages\litellm\litellm_core_utils\model_param_helper.py", line 126, in _get_litellm_supported_transcription_kwargs
    return set(TranscriptionCreateParams.__annotations__.keys())
               ^^^^^^^^^^^^^^^^^^^^^^^^^^^^^^^^^^^^^^^^^
  File "C:\Python312\Lib\typing.py", line 1213, in __getattr__
    raise AttributeError(attr)
AttributeError: __annotations__
[92m20:41:15 - LiteLLM:ERROR[0m: caching.py:563 - LiteLLM Cache: Excepton add_cache: __annotations__
Traceback (most recent call last):
  File "C:\Users\PC\AppData\Roaming\Python\Python312\site-packages\litellm\caching\caching.py", line 558, in add_cache
    cache_key, cached_data, kwargs = self._add_cache_logic(
                                     ^^^^^^^^^^^^^^^^^^^^^^
  File "C:\Users\PC\AppData\Roaming\Python\Python312\site-packages\litellm\caching\caching.py", line 542, in _add_cache_logic
    raise e
  File "C:\Users\PC\AppData\Roaming\Python\Python312\site-packages\litellm\caching\caching.py", line 522, in _add_cache_logic
    cache_key = self.get_cache_key(**kwargs)
                ^^^^^^^^^^^^^^^^^^^^^^^^^^^^
  File "C:\Users\PC\AppData\Roaming\Python\Python312\site-packages\litellm\caching\caching.py", line 248, in get_cache_key
    combined_kwargs = ModelParamHelper._get_all_llm_api_params()
                      ^^^^^^^^^^^^^^^^^^^^^^^^^^^^^^^^^^^^^^^^^^
  File "C:\Users\PC\AppData\Roaming\Python\Python312\site-packages\litellm\litellm_core_utils\model_param_helper.py", line 65, in _get_all_llm_api_params
    ModelParamHelper._get_litellm_supported_transcription_kwargs()
  File "C:\Users\PC\AppData\Roaming\Python\Python312\site-packages\litellm\litellm_core_utils\model_param_helper.py", line 126, in _get_litellm_supported_transcription_kwargs
    return set(TranscriptionCreateParams.__annotations__.keys())
               ^^^^^^^^^^^^^^^^^^^^^^^^^^^^^^^^^^^^^^^^^
  File "C:\Python312\Lib\typing.py", line 1213, in __getattr__
    raise AttributeError(attr)
AttributeError: __annotations__
[92m20:41:15 - LiteLLM:ERROR[0m: litellm_logging.py:3482 - Error creating standard logging object - __annotations__
Traceback (most recent call last):
  File "C:\Users\PC\AppData\Roaming\Python\Python312\site-packages\litellm\litellm_core_utils\litellm_logging.py", line 3464, in get_standard_logging_object_payload
    model_parameters=ModelParamHelper.get_standard_logging_model_parameters(
                     ^^^^^^^^^^^^^^^^^^^^^^^^^^^^^^^^^^^^^^^^^^^^^^^^^^^^^^^
  File "C:\Users\PC\AppData\Roaming\Python\Python312\site-packages\litellm\litellm_core_utils\model_param_helper.py", line 28, in get_standard_logging_model_parameters
    ModelParamHelper._get_relevant_args_to_use_for_logging()
  File "C:\Users\PC\AppData\Roaming\Python\Python312\site-packages\litellm\litellm_core_utils\model_param_helper.py", line 45, in _get_relevant_args_to_use_for_logging
    all_openai_llm_api_params = ModelParamHelper._get_all_llm_api_params()
                                ^^^^^^^^^^^^^^^^^^^^^^^^^^^^^^^^^^^^^^^^^^
  File "C:\Users\PC\AppData\Roaming\Python\Python312\site-packages\litellm\litellm_core_utils\model_param_helper.py", line 65, in _get_all_llm_api_params
    ModelParamHelper._get_litellm_supported_transcription_kwargs()
  File "C:\Users\PC\AppData\Roaming\Python\Python312\site-packages\litellm\litellm_core_utils\model_param_helper.py", line 126, in _get_litellm_supported_transcription_kwargs
    return set(TranscriptionCreateParams.__annotations__.keys())
               ^^^^^^^^^^^^^^^^^^^^^^^^^^^^^^^^^^^^^^^^^
  File "C:\Python312\Lib\typing.py", line 1213, in __getattr__
    raise AttributeError(attr)
AttributeError: __annotations__
[92m20:41:15 - LiteLLM:ERROR[0m: litellm_logging.py:3482 - Error creating standard logging object - __annotations__
Traceback (most recent call last):
  File "C:\Users\PC\AppData\Roaming\Python\Python312\site-packages\litellm\litellm_core_utils\litellm_logging.py", line 3464, in get_standard_logging_object_payload
    model_parameters=ModelParamHelper.get_standard_logging_model_parameters(
                     ^^^^^^^^^^^^^^^^^^^^^^^^^^^^^^^^^^^^^^^^^^^^^^^^^^^^^^^
  File "C:\Users\PC\AppData\Roaming\Python\Python312\site-packages\litellm\litellm_core_utils\model_param_helper.py", line 28, in get_standard_logging_model_parameters
    ModelParamHelper._get_relevant_args_to_use_for_logging()
  File "C:\Users\PC\AppData\Roaming\Python\Python312\site-packages\litellm\litellm_core_utils\model_param_helper.py", line 45, in _get_relevant_args_to_use_for_logging
    all_openai_llm_api_params = ModelParamHelper._get_all_llm_api_params()
                                ^^^^^^^^^^^^^^^^^^^^^^^^^^^^^^^^^^^^^^^^^^
  File "C:\Users\PC\AppData\Roaming\Python\Python312\site-packages\litellm\litellm_core_utils\model_param_helper.py", line 65, in _get_all_llm_api_params
    ModelParamHelper._get_litellm_supported_transcription_kwargs()
  File "C:\Users\PC\AppData\Roaming\Python\Python312\site-packages\litellm\litellm_core_utils\model_param_helper.py", line 126, in _get_litellm_supported_transcription_kwargs
    return set(TranscriptionCreateParams.__annotations__.keys())
               ^^^^^^^^^^^^^^^^^^^^^^^^^^^^^^^^^^^^^^^^^
  File "C:\Python312\Lib\typing.py", line 1213, in __getattr__
    raise AttributeError(attr)
AttributeError: __annotations__
[92m20:41:18 - LiteLLM:ERROR[0m: caching.py:563 - LiteLLM Cache: Excepton add_cache: __annotations__
Traceback (most recent call last):
  File "C:\Users\PC\AppData\Roaming\Python\Python312\site-packages\litellm\caching\caching.py", line 558, in add_cache
    cache_key, cached_data, kwargs = self._add_cache_logic(
                                     ^^^^^^^^^^^^^^^^^^^^^^
  File "C:\Users\PC\AppData\Roaming\Python\Python312\site-packages\litellm\caching\caching.py", line 542, in _add_cache_logic
    raise e
  File "C:\Users\PC\AppData\Roaming\Python\Python312\site-packages\litellm\caching\caching.py", line 522, in _add_cache_logic
    cache_key = self.get_cache_key(**kwargs)
                ^^^^^^^^^^^^^^^^^^^^^^^^^^^^
  File "C:\Users\PC\AppData\Roaming\Python\Python312\site-packages\litellm\caching\caching.py", line 248, in get_cache_key
    combined_kwargs = ModelParamHelper._get_all_llm_api_params()
                      ^^^^^^^^^^^^^^^^^^^^^^^^^^^^^^^^^^^^^^^^^^
  File "C:\Users\PC\AppData\Roaming\Python\Python312\site-packages\litellm\litellm_core_utils\model_param_helper.py", line 65, in _get_all_llm_api_params
    ModelParamHelper._get_litellm_supported_transcription_kwargs()
  File "C:\Users\PC\AppData\Roaming\Python\Python312\site-packages\litellm\litellm_core_utils\model_param_helper.py", line 126, in _get_litellm_supported_transcription_kwargs
    return set(TranscriptionCreateParams.__annotations__.keys())
               ^^^^^^^^^^^^^^^^^^^^^^^^^^^^^^^^^^^^^^^^^
  File "C:\Python312\Lib\typing.py", line 1213, in __getattr__
    raise AttributeError(attr)
AttributeError: __annotations__
[92m20:41:18 - LiteLLM:ERROR[0m: litellm_logging.py:3482 - Error creating standard logging object - __annotations__
Traceback (most recent call last):
  File "C:\Users\PC\AppData\Roaming\Python\Python312\site-packages\litellm\litellm_core_utils\litellm_logging.py", line 3464, in get_standard_logging_object_payload
    model_parameters=ModelParamHelper.get_standard_logging_model_parameters(
                     ^^^^^^^^^^^^^^^^^^^^^^^^^^^^^^^^^^^^^^^^^^^^^^^^^^^^^^^
  File "C:\Users\PC\AppData\Roaming\Python\Python312\site-packages\litellm\litellm_core_utils\model_param_helper.py", line 28, in get_standard_logging_model_parameters
    ModelParamHelper._get_relevant_args_to_use_for_logging()
  File "C:\Users\PC\AppData\Roaming\Python\Python312\site-packages\litellm\litellm_core_utils\model_param_helper.py", line 45, in _get_relevant_args_to_use_for_logging
    all_openai_llm_api_params = ModelParamHelper._get_all_llm_api_params()
                                ^^^^^^^^^^^^^^^^^^^^^^^^^^^^^^^^^^^^^^^^^^
  File "C:\Users\PC\AppData\Roaming\Python\Python312\site-packages\litellm\litellm_core_utils\model_param_helper.py", line 65, in _get_all_llm_api_params
    ModelParamHelper._get_litellm_supported_transcription_kwargs()
  File "C:\Users\PC\AppData\Roaming\Python\Python312\site-packages\litellm\litellm_core_utils\model_param_helper.py", line 126, in _get_litellm_supported_transcription_kwargs
    return set(TranscriptionCreateParams.__annotations__.keys())
               ^^^^^^^^^^^^^^^^^^^^^^^^^^^^^^^^^^^^^^^^^
  File "C:\Python312\Lib\typing.py", line 1213, in __getattr__
    raise AttributeError(attr)
AttributeError: __annotations__
[92m20:41:18 - LiteLLM:ERROR[0m: litellm_logging.py:3482 - Error creating standard logging object - __annotations__
Traceback (most recent call last):
  File "C:\Users\PC\AppData\Roaming\Python\Python312\site-packages\litellm\litellm_core_utils\litellm_logging.py", line 3464, in get_standard_logging_object_payload
    model_parameters=ModelParamHelper.get_standard_logging_model_parameters(
                     ^^^^^^^^^^^^^^^^^^^^^^^^^^^^^^^^^^^^^^^^^^^^^^^^^^^^^^^
  File "C:\Users\PC\AppData\Roaming\Python\Python312\site-packages\litellm\litellm_core_utils\model_param_helper.py", line 28, in get_standard_logging_model_parameters
    ModelParamHelper._get_relevant_args_to_use_for_logging()
  File "C:\Users\PC\AppData\Roaming\Python\Python312\site-packages\litellm\litellm_core_utils\model_param_helper.py", line 45, in _get_relevant_args_to_use_for_logging
    all_openai_llm_api_params = ModelParamHelper._get_all_llm_api_params()
                                ^^^^^^^^^^^^^^^^^^^^^^^^^^^^^^^^^^^^^^^^^^
  File "C:\Users\PC\AppData\Roaming\Python\Python312\site-packages\litellm\litellm_core_utils\model_param_helper.py", line 65, in _get_all_llm_api_params
    ModelParamHelper._get_litellm_supported_transcription_kwargs()
  File "C:\Users\PC\AppData\Roaming\Python\Python312\site-packages\litellm\litellm_core_utils\model_param_helper.py", line 126, in _get_litellm_supported_transcription_kwargs
    return set(TranscriptionCreateParams.__annotations__.keys())
               ^^^^^^^^^^^^^^^^^^^^^^^^^^^^^^^^^^^^^^^^^
  File "C:\Python312\Lib\typing.py", line 1213, in __getattr__
    raise AttributeError(attr)
AttributeError: __annotations__
[92m20:41:23 - LiteLLM:ERROR[0m: caching.py:563 - LiteLLM Cache: Excepton add_cache: __annotations__
Traceback (most recent call last):
  File "C:\Users\PC\AppData\Roaming\Python\Python312\site-packages\litellm\caching\caching.py", line 558, in add_cache
    cache_key, cached_data, kwargs = self._add_cache_logic(
                                     ^^^^^^^^^^^^^^^^^^^^^^
  File "C:\Users\PC\AppData\Roaming\Python\Python312\site-packages\litellm\caching\caching.py", line 542, in _add_cache_logic
    raise e
  File "C:\Users\PC\AppData\Roaming\Python\Python312\site-packages\litellm\caching\caching.py", line 522, in _add_cache_logic
    cache_key = self.get_cache_key(**kwargs)
                ^^^^^^^^^^^^^^^^^^^^^^^^^^^^
  File "C:\Users\PC\AppData\Roaming\Python\Python312\site-packages\litellm\caching\caching.py", line 248, in get_cache_key
    combined_kwargs = ModelParamHelper._get_all_llm_api_params()
                      ^^^^^^^^^^^^^^^^^^^^^^^^^^^^^^^^^^^^^^^^^^
  File "C:\Users\PC\AppData\Roaming\Python\Python312\site-packages\litellm\litellm_core_utils\model_param_helper.py", line 65, in _get_all_llm_api_params
    ModelParamHelper._get_litellm_supported_transcription_kwargs()
  File "C:\Users\PC\AppData\Roaming\Python\Python312\site-packages\litellm\litellm_core_utils\model_param_helper.py", line 126, in _get_litellm_supported_transcription_kwargs
    return set(TranscriptionCreateParams.__annotations__.keys())
               ^^^^^^^^^^^^^^^^^^^^^^^^^^^^^^^^^^^^^^^^^
  File "C:\Python312\Lib\typing.py", line 1213, in __getattr__
    raise AttributeError(attr)
AttributeError: __annotations__
[92m20:41:23 - LiteLLM:ERROR[0m: litellm_logging.py:3482 - Error creating standard logging object - __annotations__
Traceback (most recent call last):
  File "C:\Users\PC\AppData\Roaming\Python\Python312\site-packages\litellm\litellm_core_utils\litellm_logging.py", line 3464, in get_standard_logging_object_payload
    model_parameters=ModelParamHelper.get_standard_logging_model_parameters(
                     ^^^^^^^^^^^^^^^^^^^^^^^^^^^^^^^^^^^^^^^^^^^^^^^^^^^^^^^
  File "C:\Users\PC\AppData\Roaming\Python\Python312\site-packages\litellm\litellm_core_utils\model_param_helper.py", line 28, in get_standard_logging_model_parameters
    ModelParamHelper._get_relevant_args_to_use_for_logging()
  File "C:\Users\PC\AppData\Roaming\Python\Python312\site-packages\litellm\litellm_core_utils\model_param_helper.py", line 45, in _get_relevant_args_to_use_for_logging
    all_openai_llm_api_params = ModelParamHelper._get_all_llm_api_params()
                                ^^^^^^^^^^^^^^^^^^^^^^^^^^^^^^^^^^^^^^^^^^
  File "C:\Users\PC\AppData\Roaming\Python\Python312\site-packages\litellm\litellm_core_utils\model_param_helper.py", line 65, in _get_all_llm_api_params
    ModelParamHelper._get_litellm_supported_transcription_kwargs()
  File "C:\Users\PC\AppData\Roaming\Python\Python312\site-packages\litellm\litellm_core_utils\model_param_helper.py", line 126, in _get_litellm_supported_transcription_kwargs
    return set(TranscriptionCreateParams.__annotations__.keys())
               ^^^^^^^^^^^^^^^^^^^^^^^^^^^^^^^^^^^^^^^^^
  File "C:\Python312\Lib\typing.py", line 1213, in __getattr__
    raise AttributeError(attr)
AttributeError: __annotations__
[92m20:41:23 - LiteLLM:ERROR[0m: litellm_logging.py:3482 - Error creating standard logging object - __annotations__
Traceback (most recent call last):
  File "C:\Users\PC\AppData\Roaming\Python\Python312\site-packages\litellm\litellm_core_utils\litellm_logging.py", line 3464, in get_standard_logging_object_payload
    model_parameters=ModelParamHelper.get_standard_logging_model_parameters(
                     ^^^^^^^^^^^^^^^^^^^^^^^^^^^^^^^^^^^^^^^^^^^^^^^^^^^^^^^
  File "C:\Users\PC\AppData\Roaming\Python\Python312\site-packages\litellm\litellm_core_utils\model_param_helper.py", line 28, in get_standard_logging_model_parameters
    ModelParamHelper._get_relevant_args_to_use_for_logging()
  File "C:\Users\PC\AppData\Roaming\Python\Python312\site-packages\litellm\litellm_core_utils\model_param_helper.py", line 45, in _get_relevant_args_to_use_for_logging
    all_openai_llm_api_params = ModelParamHelper._get_all_llm_api_params()
                                ^^^^^^^^^^^^^^^^^^^^^^^^^^^^^^^^^^^^^^^^^^
  File "C:\Users\PC\AppData\Roaming\Python\Python312\site-packages\litellm\litellm_core_utils\model_param_helper.py", line 65, in _get_all_llm_api_params
    ModelParamHelper._get_litellm_supported_transcription_kwargs()
  File "C:\Users\PC\AppData\Roaming\Python\Python312\site-packages\litellm\litellm_core_utils\model_param_helper.py", line 126, in _get_litellm_supported_transcription_kwargs
    return set(TranscriptionCreateParams.__annotations__.keys())
               ^^^^^^^^^^^^^^^^^^^^^^^^^^^^^^^^^^^^^^^^^
  File "C:\Python312\Lib\typing.py", line 1213, in __getattr__
    raise AttributeError(attr)
AttributeError: __annotations__
[92m20:41:26 - LiteLLM:ERROR[0m: caching.py:563 - LiteLLM Cache: Excepton add_cache: __annotations__
Traceback (most recent call last):
  File "C:\Users\PC\AppData\Roaming\Python\Python312\site-packages\dspy\adapters\chat_adapter.py", line 111, in parse
    fields[k] = parse_value(v, signature.output_fields[k].annotation)
                ^^^^^^^^^^^^^^^^^^^^^^^^^^^^^^^^^^^^^^^^^^^^^^^^^^^^^
  File "C:\Users\PC\AppData\Roaming\Python\Python312\site-packages\dspy\adapters\utils.py", line 106, in parse_value
    return TypeAdapter(annotation).validate_python(candidate)
           ^^^^^^^^^^^^^^^^^^^^^^^^^^^^^^^^^^^^^^^^^^^^^^^^^^
  File "C:\Users\PC\AppData\Roaming\Python\Python312\site-packages\pydantic\type_adapter.py", line 135, in wrapped
    return func(self, *args, **kwargs)
           ^^^^^^^^^^^^^^^^^^^^^^^^^^^
  File "C:\Users\PC\AppData\Roaming\Python\Python312\site-packages\pydantic\type_adapter.py", line 366, in validate_python
    return self.validator.validate_python(object, strict=strict, from_attributes=from_attributes, context=context)
           ^^^^^^^^^^^^^^^^^^^^^^^^^^^^^^^^^^^^^^^^^^^^^^^^^^^^^^^^^^^^^^^^^^^^^^^^^^^^^^^^^^^^^^^^^^^^^^^^^^^^^^^
pydantic_core._pydantic_core.ValidationError: 10 validation errors for list[str]
0
  Input should be a valid string [type=string_type, input_value={'s': 'abc', 'output_result': 'YES'}, input_type=dict]
    For further information visit https://errors.pydantic.dev/2.9/v/string_type
1
  Input should be a valid string [type=string_type, input_value={'s': 'acb', 'output_result': 'YES'}, input_type=dict]
    For further information visit https://errors.pydantic.dev/2.9/v/string_type
2
  Input should be a valid string [type=string_type, input_value={'s': 'bac', 'output_result': 'YES'}, input_type=dict]
    For further information visit https://errors.pydantic.dev/2.9/v/string_type
3
  Input should be a valid string [type=string_type, input_value={'s': 'bca', 'output_result': 'YES'}, input_type=dict]
    For further information visit https://errors.pydantic.dev/2.9/v/string_type
4
  Input should be a valid string [type=string_type, input_value={'s': 'cba', 'output_result': 'NO'}, input_type=dict]
    For further information visit https://errors.pydantic.dev/2.9/v/string_type
5
  Input should be a valid string [type=string_type, input_value={'s': 'aaa', 'output_result': 'NO'}, input_type=dict]
    For further information visit https://errors.pydantic.dev/2.9/v/string_type
6
  Input should be a valid string [type=string_type, input_value={'s': 'aab', 'output_result': 'NO'}, input_type=dict]
    For further information visit https://errors.pydantic.dev/2.9/v/string_type
7
  Input should be a valid string [type=string_type, input_value={'s': 'abcabc', 'output_result': 'NO'}, input_type=dict]
    For further information visit https://errors.pydantic.dev/2.9/v/string_type
8
  Input should be a valid string [type=string_type, input_value={'s': 'ab', 'output_result': 'NO'}, input_type=dict]
    For further information visit https://errors.pydantic.dev/2.9/v/string_type
9
  Input should be a valid string [type=string_type, input_value={'s': 'cab', 'output_result': 'YES'}, input_type=dict]
    For further information visit https://errors.pydantic.dev/2.9/v/string_type

During handling of the above exception, another exception occurred:

Traceback (most recent call last):
  File "C:\Users\PC\AppData\Roaming\Python\Python312\site-packages\dspy\adapters\chat_adapter.py", line 49, in __call__
    return super().__call__(lm, lm_kwargs, signature, demos, inputs)
           ^^^^^^^^^^^^^^^^^^^^^^^^^^^^^^^^^^^^^^^^^^^^^^^^^^^^^^^^^
  File "C:\Users\PC\AppData\Roaming\Python\Python312\site-packages\dspy\adapters\base.py", line 43, in __call__
    value = self.parse(signature, output)
            ^^^^^^^^^^^^^^^^^^^^^^^^^^^^^
  File "C:\Users\PC\AppData\Roaming\Python\Python312\site-packages\dspy\utils\callback.py", line 266, in wrapper
    return fn(instance, *args, **kwargs)
           ^^^^^^^^^^^^^^^^^^^^^^^^^^^^^
  File "C:\Users\PC\AppData\Roaming\Python\Python312\site-packages\dspy\adapters\chat_adapter.py", line 113, in parse
    raise ValueError(
ValueError: Error parsing field test_cases: 10 validation errors for list[str]
0
  Input should be a valid string [type=string_type, input_value={'s': 'abc', 'output_result': 'YES'}, input_type=dict]
    For further information visit https://errors.pydantic.dev/2.9/v/string_type
1
  Input should be a valid string [type=string_type, input_value={'s': 'acb', 'output_result': 'YES'}, input_type=dict]
    For further information visit https://errors.pydantic.dev/2.9/v/string_type
2
  Input should be a valid string [type=string_type, input_value={'s': 'bac', 'output_result': 'YES'}, input_type=dict]
    For further information visit https://errors.pydantic.dev/2.9/v/string_type
3
  Input should be a valid string [type=string_type, input_value={'s': 'bca', 'output_result': 'YES'}, input_type=dict]
    For further information visit https://errors.pydantic.dev/2.9/v/string_type
4
  Input should be a valid string [type=string_type, input_value={'s': 'cba', 'output_result': 'NO'}, input_type=dict]
    For further information visit https://errors.pydantic.dev/2.9/v/string_type
5
  Input should be a valid string [type=string_type, input_value={'s': 'aaa', 'output_result': 'NO'}, input_type=dict]
    For further information visit https://errors.pydantic.dev/2.9/v/string_type
6
  Input should be a valid string [type=string_type, input_value={'s': 'aab', 'output_result': 'NO'}, input_type=dict]
    For further information visit https://errors.pydantic.dev/2.9/v/string_type
7
  Input should be a valid string [type=string_type, input_value={'s': 'abcabc', 'output_result': 'NO'}, input_type=dict]
    For further information visit https://errors.pydantic.dev/2.9/v/string_type
8
  Input should be a valid string [type=string_type, input_value={'s': 'ab', 'output_result': 'NO'}, input_type=dict]
    For further information visit https://errors.pydantic.dev/2.9/v/string_type
9
  Input should be a valid string [type=string_type, input_value={'s': 'cab', 'output_result': 'YES'}, input_type=dict]
    For further information visit https://errors.pydantic.dev/2.9/v/string_type.

		On attempting to parse the value
```
[
    {"s": "abc", "output_result": "YES"},
    {"s": "acb", "output_result": "YES"},
    {"s": "bac", "output_result": "YES"},
    {"s": "bca", "output_result": "YES"},
    {"s": "cba", "output_result": "NO"},
    {"s": "aaa", "output_result": "NO"},
    {"s": "aab", "output_result": "NO"},
    {"s": "abcabc", "output_result": "NO"},
    {"s": "ab", "output_result": "NO"},
    {"s": "cab", "output_result": "YES"}
]
```

During handling of the above exception, another exception occurred:

Traceback (most recent call last):
  File "C:\Users\PC\AppData\Roaming\Python\Python312\site-packages\litellm\caching\caching.py", line 558, in add_cache
    cache_key, cached_data, kwargs = self._add_cache_logic(
                                     ^^^^^^^^^^^^^^^^^^^^^^
  File "C:\Users\PC\AppData\Roaming\Python\Python312\site-packages\litellm\caching\caching.py", line 542, in _add_cache_logic
    raise e
  File "C:\Users\PC\AppData\Roaming\Python\Python312\site-packages\litellm\caching\caching.py", line 522, in _add_cache_logic
    cache_key = self.get_cache_key(**kwargs)
                ^^^^^^^^^^^^^^^^^^^^^^^^^^^^
  File "C:\Users\PC\AppData\Roaming\Python\Python312\site-packages\litellm\caching\caching.py", line 248, in get_cache_key
    combined_kwargs = ModelParamHelper._get_all_llm_api_params()
                      ^^^^^^^^^^^^^^^^^^^^^^^^^^^^^^^^^^^^^^^^^^
  File "C:\Users\PC\AppData\Roaming\Python\Python312\site-packages\litellm\litellm_core_utils\model_param_helper.py", line 65, in _get_all_llm_api_params
    ModelParamHelper._get_litellm_supported_transcription_kwargs()
  File "C:\Users\PC\AppData\Roaming\Python\Python312\site-packages\litellm\litellm_core_utils\model_param_helper.py", line 126, in _get_litellm_supported_transcription_kwargs
    return set(TranscriptionCreateParams.__annotations__.keys())
               ^^^^^^^^^^^^^^^^^^^^^^^^^^^^^^^^^^^^^^^^^
  File "C:\Python312\Lib\typing.py", line 1213, in __getattr__
    raise AttributeError(attr)
AttributeError: __annotations__
[92m20:41:26 - LiteLLM:ERROR[0m: litellm_logging.py:3482 - Error creating standard logging object - __annotations__
Traceback (most recent call last):
  File "C:\Users\PC\AppData\Roaming\Python\Python312\site-packages\litellm\litellm_core_utils\litellm_logging.py", line 3464, in get_standard_logging_object_payload
    model_parameters=ModelParamHelper.get_standard_logging_model_parameters(
                     ^^^^^^^^^^^^^^^^^^^^^^^^^^^^^^^^^^^^^^^^^^^^^^^^^^^^^^^
  File "C:\Users\PC\AppData\Roaming\Python\Python312\site-packages\litellm\litellm_core_utils\model_param_helper.py", line 28, in get_standard_logging_model_parameters
    ModelParamHelper._get_relevant_args_to_use_for_logging()
  File "C:\Users\PC\AppData\Roaming\Python\Python312\site-packages\litellm\litellm_core_utils\model_param_helper.py", line 45, in _get_relevant_args_to_use_for_logging
    all_openai_llm_api_params = ModelParamHelper._get_all_llm_api_params()
                                ^^^^^^^^^^^^^^^^^^^^^^^^^^^^^^^^^^^^^^^^^^
  File "C:\Users\PC\AppData\Roaming\Python\Python312\site-packages\litellm\litellm_core_utils\model_param_helper.py", line 65, in _get_all_llm_api_params
    ModelParamHelper._get_litellm_supported_transcription_kwargs()
  File "C:\Users\PC\AppData\Roaming\Python\Python312\site-packages\litellm\litellm_core_utils\model_param_helper.py", line 126, in _get_litellm_supported_transcription_kwargs
    return set(TranscriptionCreateParams.__annotations__.keys())
               ^^^^^^^^^^^^^^^^^^^^^^^^^^^^^^^^^^^^^^^^^
  File "C:\Python312\Lib\typing.py", line 1213, in __getattr__
    raise AttributeError(attr)
AttributeError: __annotations__
[92m20:41:26 - LiteLLM:ERROR[0m: litellm_logging.py:3482 - Error creating standard logging object - __annotations__
Traceback (most recent call last):
  File "C:\Users\PC\AppData\Roaming\Python\Python312\site-packages\litellm\litellm_core_utils\litellm_logging.py", line 3464, in get_standard_logging_object_payload
    model_parameters=ModelParamHelper.get_standard_logging_model_parameters(
                     ^^^^^^^^^^^^^^^^^^^^^^^^^^^^^^^^^^^^^^^^^^^^^^^^^^^^^^^
  File "C:\Users\PC\AppData\Roaming\Python\Python312\site-packages\litellm\litellm_core_utils\model_param_helper.py", line 28, in get_standard_logging_model_parameters
    ModelParamHelper._get_relevant_args_to_use_for_logging()
  File "C:\Users\PC\AppData\Roaming\Python\Python312\site-packages\litellm\litellm_core_utils\model_param_helper.py", line 45, in _get_relevant_args_to_use_for_logging
    all_openai_llm_api_params = ModelParamHelper._get_all_llm_api_params()
                                ^^^^^^^^^^^^^^^^^^^^^^^^^^^^^^^^^^^^^^^^^^
  File "C:\Users\PC\AppData\Roaming\Python\Python312\site-packages\litellm\litellm_core_utils\model_param_helper.py", line 65, in _get_all_llm_api_params
    ModelParamHelper._get_litellm_supported_transcription_kwargs()
  File "C:\Users\PC\AppData\Roaming\Python\Python312\site-packages\litellm\litellm_core_utils\model_param_helper.py", line 126, in _get_litellm_supported_transcription_kwargs
    return set(TranscriptionCreateParams.__annotations__.keys())
               ^^^^^^^^^^^^^^^^^^^^^^^^^^^^^^^^^^^^^^^^^
  File "C:\Python312\Lib\typing.py", line 1213, in __getattr__
    raise AttributeError(attr)
AttributeError: __annotations__
[92m20:41:30 - LiteLLM:ERROR[0m: caching.py:563 - LiteLLM Cache: Excepton add_cache: __annotations__
Traceback (most recent call last):
  File "C:\Users\PC\AppData\Roaming\Python\Python312\site-packages\litellm\caching\caching.py", line 558, in add_cache
    cache_key, cached_data, kwargs = self._add_cache_logic(
                                     ^^^^^^^^^^^^^^^^^^^^^^
  File "C:\Users\PC\AppData\Roaming\Python\Python312\site-packages\litellm\caching\caching.py", line 542, in _add_cache_logic
    raise e
  File "C:\Users\PC\AppData\Roaming\Python\Python312\site-packages\litellm\caching\caching.py", line 522, in _add_cache_logic
    cache_key = self.get_cache_key(**kwargs)
                ^^^^^^^^^^^^^^^^^^^^^^^^^^^^
  File "C:\Users\PC\AppData\Roaming\Python\Python312\site-packages\litellm\caching\caching.py", line 248, in get_cache_key
    combined_kwargs = ModelParamHelper._get_all_llm_api_params()
                      ^^^^^^^^^^^^^^^^^^^^^^^^^^^^^^^^^^^^^^^^^^
  File "C:\Users\PC\AppData\Roaming\Python\Python312\site-packages\litellm\litellm_core_utils\model_param_helper.py", line 65, in _get_all_llm_api_params
    ModelParamHelper._get_litellm_supported_transcription_kwargs()
  File "C:\Users\PC\AppData\Roaming\Python\Python312\site-packages\litellm\litellm_core_utils\model_param_helper.py", line 126, in _get_litellm_supported_transcription_kwargs
    return set(TranscriptionCreateParams.__annotations__.keys())
               ^^^^^^^^^^^^^^^^^^^^^^^^^^^^^^^^^^^^^^^^^
  File "C:\Python312\Lib\typing.py", line 1213, in __getattr__
    raise AttributeError(attr)
AttributeError: __annotations__
[92m20:41:30 - LiteLLM:ERROR[0m: litellm_logging.py:3482 - Error creating standard logging object - __annotations__
Traceback (most recent call last):
  File "C:\Users\PC\AppData\Roaming\Python\Python312\site-packages\litellm\litellm_core_utils\litellm_logging.py", line 3464, in get_standard_logging_object_payload
    model_parameters=ModelParamHelper.get_standard_logging_model_parameters(
                     ^^^^^^^^^^^^^^^^^^^^^^^^^^^^^^^^^^^^^^^^^^^^^^^^^^^^^^^
  File "C:\Users\PC\AppData\Roaming\Python\Python312\site-packages\litellm\litellm_core_utils\model_param_helper.py", line 28, in get_standard_logging_model_parameters
    ModelParamHelper._get_relevant_args_to_use_for_logging()
  File "C:\Users\PC\AppData\Roaming\Python\Python312\site-packages\litellm\litellm_core_utils\model_param_helper.py", line 45, in _get_relevant_args_to_use_for_logging
    all_openai_llm_api_params = ModelParamHelper._get_all_llm_api_params()
                                ^^^^^^^^^^^^^^^^^^^^^^^^^^^^^^^^^^^^^^^^^^
  File "C:\Users\PC\AppData\Roaming\Python\Python312\site-packages\litellm\litellm_core_utils\model_param_helper.py", line 65, in _get_all_llm_api_params
    ModelParamHelper._get_litellm_supported_transcription_kwargs()
  File "C:\Users\PC\AppData\Roaming\Python\Python312\site-packages\litellm\litellm_core_utils\model_param_helper.py", line 126, in _get_litellm_supported_transcription_kwargs
    return set(TranscriptionCreateParams.__annotations__.keys())
               ^^^^^^^^^^^^^^^^^^^^^^^^^^^^^^^^^^^^^^^^^
  File "C:\Python312\Lib\typing.py", line 1213, in __getattr__
    raise AttributeError(attr)
AttributeError: __annotations__
[92m20:41:30 - LiteLLM:ERROR[0m: litellm_logging.py:3482 - Error creating standard logging object - __annotations__
Traceback (most recent call last):
  File "C:\Users\PC\AppData\Roaming\Python\Python312\site-packages\litellm\litellm_core_utils\litellm_logging.py", line 3464, in get_standard_logging_object_payload
    model_parameters=ModelParamHelper.get_standard_logging_model_parameters(
                     ^^^^^^^^^^^^^^^^^^^^^^^^^^^^^^^^^^^^^^^^^^^^^^^^^^^^^^^
  File "C:\Users\PC\AppData\Roaming\Python\Python312\site-packages\litellm\litellm_core_utils\model_param_helper.py", line 28, in get_standard_logging_model_parameters
    ModelParamHelper._get_relevant_args_to_use_for_logging()
  File "C:\Users\PC\AppData\Roaming\Python\Python312\site-packages\litellm\litellm_core_utils\model_param_helper.py", line 45, in _get_relevant_args_to_use_for_logging
    all_openai_llm_api_params = ModelParamHelper._get_all_llm_api_params()
                                ^^^^^^^^^^^^^^^^^^^^^^^^^^^^^^^^^^^^^^^^^^
  File "C:\Users\PC\AppData\Roaming\Python\Python312\site-packages\litellm\litellm_core_utils\model_param_helper.py", line 65, in _get_all_llm_api_params
    ModelParamHelper._get_litellm_supported_transcription_kwargs()
  File "C:\Users\PC\AppData\Roaming\Python\Python312\site-packages\litellm\litellm_core_utils\model_param_helper.py", line 126, in _get_litellm_supported_transcription_kwargs
    return set(TranscriptionCreateParams.__annotations__.keys())
               ^^^^^^^^^^^^^^^^^^^^^^^^^^^^^^^^^^^^^^^^^
  File "C:\Python312\Lib\typing.py", line 1213, in __getattr__
    raise AttributeError(attr)
AttributeError: __annotations__
[92m20:41:33 - LiteLLM:ERROR[0m: caching.py:563 - LiteLLM Cache: Excepton add_cache: __annotations__
Traceback (most recent call last):
  File "C:\Users\PC\AppData\Roaming\Python\Python312\site-packages\litellm\caching\caching.py", line 558, in add_cache
    cache_key, cached_data, kwargs = self._add_cache_logic(
                                     ^^^^^^^^^^^^^^^^^^^^^^
  File "C:\Users\PC\AppData\Roaming\Python\Python312\site-packages\litellm\caching\caching.py", line 542, in _add_cache_logic
    raise e
  File "C:\Users\PC\AppData\Roaming\Python\Python312\site-packages\litellm\caching\caching.py", line 522, in _add_cache_logic
    cache_key = self.get_cache_key(**kwargs)
                ^^^^^^^^^^^^^^^^^^^^^^^^^^^^
  File "C:\Users\PC\AppData\Roaming\Python\Python312\site-packages\litellm\caching\caching.py", line 248, in get_cache_key
    combined_kwargs = ModelParamHelper._get_all_llm_api_params()
                      ^^^^^^^^^^^^^^^^^^^^^^^^^^^^^^^^^^^^^^^^^^
  File "C:\Users\PC\AppData\Roaming\Python\Python312\site-packages\litellm\litellm_core_utils\model_param_helper.py", line 65, in _get_all_llm_api_params
    ModelParamHelper._get_litellm_supported_transcription_kwargs()
  File "C:\Users\PC\AppData\Roaming\Python\Python312\site-packages\litellm\litellm_core_utils\model_param_helper.py", line 126, in _get_litellm_supported_transcription_kwargs
    return set(TranscriptionCreateParams.__annotations__.keys())
               ^^^^^^^^^^^^^^^^^^^^^^^^^^^^^^^^^^^^^^^^^
  File "C:\Python312\Lib\typing.py", line 1213, in __getattr__
    raise AttributeError(attr)
AttributeError: __annotations__
[92m20:41:33 - LiteLLM:ERROR[0m: litellm_logging.py:3482 - Error creating standard logging object - __annotations__
Traceback (most recent call last):
  File "C:\Users\PC\AppData\Roaming\Python\Python312\site-packages\litellm\litellm_core_utils\litellm_logging.py", line 3464, in get_standard_logging_object_payload
    model_parameters=ModelParamHelper.get_standard_logging_model_parameters(
                     ^^^^^^^^^^^^^^^^^^^^^^^^^^^^^^^^^^^^^^^^^^^^^^^^^^^^^^^
  File "C:\Users\PC\AppData\Roaming\Python\Python312\site-packages\litellm\litellm_core_utils\model_param_helper.py", line 28, in get_standard_logging_model_parameters
    ModelParamHelper._get_relevant_args_to_use_for_logging()
  File "C:\Users\PC\AppData\Roaming\Python\Python312\site-packages\litellm\litellm_core_utils\model_param_helper.py", line 45, in _get_relevant_args_to_use_for_logging
    all_openai_llm_api_params = ModelParamHelper._get_all_llm_api_params()
                                ^^^^^^^^^^^^^^^^^^^^^^^^^^^^^^^^^^^^^^^^^^
  File "C:\Users\PC\AppData\Roaming\Python\Python312\site-packages\litellm\litellm_core_utils\model_param_helper.py", line 65, in _get_all_llm_api_params
    ModelParamHelper._get_litellm_supported_transcription_kwargs()
  File "C:\Users\PC\AppData\Roaming\Python\Python312\site-packages\litellm\litellm_core_utils\model_param_helper.py", line 126, in _get_litellm_supported_transcription_kwargs
    return set(TranscriptionCreateParams.__annotations__.keys())
               ^^^^^^^^^^^^^^^^^^^^^^^^^^^^^^^^^^^^^^^^^
  File "C:\Python312\Lib\typing.py", line 1213, in __getattr__
    raise AttributeError(attr)
AttributeError: __annotations__
[92m20:41:33 - LiteLLM:ERROR[0m: litellm_logging.py:3482 - Error creating standard logging object - __annotations__
Traceback (most recent call last):
  File "C:\Users\PC\AppData\Roaming\Python\Python312\site-packages\litellm\litellm_core_utils\litellm_logging.py", line 3464, in get_standard_logging_object_payload
    model_parameters=ModelParamHelper.get_standard_logging_model_parameters(
                     ^^^^^^^^^^^^^^^^^^^^^^^^^^^^^^^^^^^^^^^^^^^^^^^^^^^^^^^
  File "C:\Users\PC\AppData\Roaming\Python\Python312\site-packages\litellm\litellm_core_utils\model_param_helper.py", line 28, in get_standard_logging_model_parameters
    ModelParamHelper._get_relevant_args_to_use_for_logging()
  File "C:\Users\PC\AppData\Roaming\Python\Python312\site-packages\litellm\litellm_core_utils\model_param_helper.py", line 45, in _get_relevant_args_to_use_for_logging
    all_openai_llm_api_params = ModelParamHelper._get_all_llm_api_params()
                                ^^^^^^^^^^^^^^^^^^^^^^^^^^^^^^^^^^^^^^^^^^
  File "C:\Users\PC\AppData\Roaming\Python\Python312\site-packages\litellm\litellm_core_utils\model_param_helper.py", line 65, in _get_all_llm_api_params
    ModelParamHelper._get_litellm_supported_transcription_kwargs()
  File "C:\Users\PC\AppData\Roaming\Python\Python312\site-packages\litellm\litellm_core_utils\model_param_helper.py", line 126, in _get_litellm_supported_transcription_kwargs
    return set(TranscriptionCreateParams.__annotations__.keys())
               ^^^^^^^^^^^^^^^^^^^^^^^^^^^^^^^^^^^^^^^^^
  File "C:\Python312\Lib\typing.py", line 1213, in __getattr__
    raise AttributeError(attr)
AttributeError: __annotations__
[92m20:41:35 - LiteLLM:ERROR[0m: caching.py:563 - LiteLLM Cache: Excepton add_cache: __annotations__
Traceback (most recent call last):
  File "C:\Users\PC\AppData\Roaming\Python\Python312\site-packages\litellm\caching\caching.py", line 558, in add_cache
    cache_key, cached_data, kwargs = self._add_cache_logic(
                                     ^^^^^^^^^^^^^^^^^^^^^^
  File "C:\Users\PC\AppData\Roaming\Python\Python312\site-packages\litellm\caching\caching.py", line 542, in _add_cache_logic
    raise e
  File "C:\Users\PC\AppData\Roaming\Python\Python312\site-packages\litellm\caching\caching.py", line 522, in _add_cache_logic
    cache_key = self.get_cache_key(**kwargs)
                ^^^^^^^^^^^^^^^^^^^^^^^^^^^^
  File "C:\Users\PC\AppData\Roaming\Python\Python312\site-packages\litellm\caching\caching.py", line 248, in get_cache_key
    combined_kwargs = ModelParamHelper._get_all_llm_api_params()
                      ^^^^^^^^^^^^^^^^^^^^^^^^^^^^^^^^^^^^^^^^^^
  File "C:\Users\PC\AppData\Roaming\Python\Python312\site-packages\litellm\litellm_core_utils\model_param_helper.py", line 65, in _get_all_llm_api_params
    ModelParamHelper._get_litellm_supported_transcription_kwargs()
  File "C:\Users\PC\AppData\Roaming\Python\Python312\site-packages\litellm\litellm_core_utils\model_param_helper.py", line 126, in _get_litellm_supported_transcription_kwargs
    return set(TranscriptionCreateParams.__annotations__.keys())
               ^^^^^^^^^^^^^^^^^^^^^^^^^^^^^^^^^^^^^^^^^
  File "C:\Python312\Lib\typing.py", line 1213, in __getattr__
    raise AttributeError(attr)
AttributeError: __annotations__
[92m20:41:35 - LiteLLM:ERROR[0m: litellm_logging.py:3482 - Error creating standard logging object - __annotations__
Traceback (most recent call last):
  File "C:\Users\PC\AppData\Roaming\Python\Python312\site-packages\litellm\litellm_core_utils\litellm_logging.py", line 3464, in get_standard_logging_object_payload
    model_parameters=ModelParamHelper.get_standard_logging_model_parameters(
                     ^^^^^^^^^^^^^^^^^^^^^^^^^^^^^^^^^^^^^^^^^^^^^^^^^^^^^^^
  File "C:\Users\PC\AppData\Roaming\Python\Python312\site-packages\litellm\litellm_core_utils\model_param_helper.py", line 28, in get_standard_logging_model_parameters
    ModelParamHelper._get_relevant_args_to_use_for_logging()
  File "C:\Users\PC\AppData\Roaming\Python\Python312\site-packages\litellm\litellm_core_utils\model_param_helper.py", line 45, in _get_relevant_args_to_use_for_logging
    all_openai_llm_api_params = ModelParamHelper._get_all_llm_api_params()
                                ^^^^^^^^^^^^^^^^^^^^^^^^^^^^^^^^^^^^^^^^^^
  File "C:\Users\PC\AppData\Roaming\Python\Python312\site-packages\litellm\litellm_core_utils\model_param_helper.py", line 65, in _get_all_llm_api_params
    ModelParamHelper._get_litellm_supported_transcription_kwargs()
  File "C:\Users\PC\AppData\Roaming\Python\Python312\site-packages\litellm\litellm_core_utils\model_param_helper.py", line 126, in _get_litellm_supported_transcription_kwargs
    return set(TranscriptionCreateParams.__annotations__.keys())
               ^^^^^^^^^^^^^^^^^^^^^^^^^^^^^^^^^^^^^^^^^
  File "C:\Python312\Lib\typing.py", line 1213, in __getattr__
    raise AttributeError(attr)
AttributeError: __annotations__
[92m20:41:35 - LiteLLM:ERROR[0m: litellm_logging.py:3482 - Error creating standard logging object - __annotations__
Traceback (most recent call last):
  File "C:\Users\PC\AppData\Roaming\Python\Python312\site-packages\litellm\litellm_core_utils\litellm_logging.py", line 3464, in get_standard_logging_object_payload
    model_parameters=ModelParamHelper.get_standard_logging_model_parameters(
                     ^^^^^^^^^^^^^^^^^^^^^^^^^^^^^^^^^^^^^^^^^^^^^^^^^^^^^^^
  File "C:\Users\PC\AppData\Roaming\Python\Python312\site-packages\litellm\litellm_core_utils\model_param_helper.py", line 28, in get_standard_logging_model_parameters
    ModelParamHelper._get_relevant_args_to_use_for_logging()
  File "C:\Users\PC\AppData\Roaming\Python\Python312\site-packages\litellm\litellm_core_utils\model_param_helper.py", line 45, in _get_relevant_args_to_use_for_logging
    all_openai_llm_api_params = ModelParamHelper._get_all_llm_api_params()
                                ^^^^^^^^^^^^^^^^^^^^^^^^^^^^^^^^^^^^^^^^^^
  File "C:\Users\PC\AppData\Roaming\Python\Python312\site-packages\litellm\litellm_core_utils\model_param_helper.py", line 65, in _get_all_llm_api_params
    ModelParamHelper._get_litellm_supported_transcription_kwargs()
  File "C:\Users\PC\AppData\Roaming\Python\Python312\site-packages\litellm\litellm_core_utils\model_param_helper.py", line 126, in _get_litellm_supported_transcription_kwargs
    return set(TranscriptionCreateParams.__annotations__.keys())
               ^^^^^^^^^^^^^^^^^^^^^^^^^^^^^^^^^^^^^^^^^
  File "C:\Python312\Lib\typing.py", line 1213, in __getattr__
    raise AttributeError(attr)
AttributeError: __annotations__
[92m20:41:39 - LiteLLM:ERROR[0m: caching.py:563 - LiteLLM Cache: Excepton add_cache: __annotations__
Traceback (most recent call last):
  File "C:\Users\PC\AppData\Roaming\Python\Python312\site-packages\litellm\caching\caching.py", line 558, in add_cache
    cache_key, cached_data, kwargs = self._add_cache_logic(
                                     ^^^^^^^^^^^^^^^^^^^^^^
  File "C:\Users\PC\AppData\Roaming\Python\Python312\site-packages\litellm\caching\caching.py", line 542, in _add_cache_logic
    raise e
  File "C:\Users\PC\AppData\Roaming\Python\Python312\site-packages\litellm\caching\caching.py", line 522, in _add_cache_logic
    cache_key = self.get_cache_key(**kwargs)
                ^^^^^^^^^^^^^^^^^^^^^^^^^^^^
  File "C:\Users\PC\AppData\Roaming\Python\Python312\site-packages\litellm\caching\caching.py", line 248, in get_cache_key
    combined_kwargs = ModelParamHelper._get_all_llm_api_params()
                      ^^^^^^^^^^^^^^^^^^^^^^^^^^^^^^^^^^^^^^^^^^
  File "C:\Users\PC\AppData\Roaming\Python\Python312\site-packages\litellm\litellm_core_utils\model_param_helper.py", line 65, in _get_all_llm_api_params
    ModelParamHelper._get_litellm_supported_transcription_kwargs()
  File "C:\Users\PC\AppData\Roaming\Python\Python312\site-packages\litellm\litellm_core_utils\model_param_helper.py", line 126, in _get_litellm_supported_transcription_kwargs
    return set(TranscriptionCreateParams.__annotations__.keys())
               ^^^^^^^^^^^^^^^^^^^^^^^^^^^^^^^^^^^^^^^^^
  File "C:\Python312\Lib\typing.py", line 1213, in __getattr__
    raise AttributeError(attr)
AttributeError: __annotations__
[92m20:41:39 - LiteLLM:ERROR[0m: litellm_logging.py:3482 - Error creating standard logging object - __annotations__
Traceback (most recent call last):
  File "C:\Users\PC\AppData\Roaming\Python\Python312\site-packages\litellm\litellm_core_utils\litellm_logging.py", line 3464, in get_standard_logging_object_payload
    model_parameters=ModelParamHelper.get_standard_logging_model_parameters(
                     ^^^^^^^^^^^^^^^^^^^^^^^^^^^^^^^^^^^^^^^^^^^^^^^^^^^^^^^
  File "C:\Users\PC\AppData\Roaming\Python\Python312\site-packages\litellm\litellm_core_utils\model_param_helper.py", line 28, in get_standard_logging_model_parameters
    ModelParamHelper._get_relevant_args_to_use_for_logging()
  File "C:\Users\PC\AppData\Roaming\Python\Python312\site-packages\litellm\litellm_core_utils\model_param_helper.py", line 45, in _get_relevant_args_to_use_for_logging
    all_openai_llm_api_params = ModelParamHelper._get_all_llm_api_params()
                                ^^^^^^^^^^^^^^^^^^^^^^^^^^^^^^^^^^^^^^^^^^
  File "C:\Users\PC\AppData\Roaming\Python\Python312\site-packages\litellm\litellm_core_utils\model_param_helper.py", line 65, in _get_all_llm_api_params
    ModelParamHelper._get_litellm_supported_transcription_kwargs()
  File "C:\Users\PC\AppData\Roaming\Python\Python312\site-packages\litellm\litellm_core_utils\model_param_helper.py", line 126, in _get_litellm_supported_transcription_kwargs
    return set(TranscriptionCreateParams.__annotations__.keys())
               ^^^^^^^^^^^^^^^^^^^^^^^^^^^^^^^^^^^^^^^^^
  File "C:\Python312\Lib\typing.py", line 1213, in __getattr__
    raise AttributeError(attr)
AttributeError: __annotations__
[92m20:41:39 - LiteLLM:ERROR[0m: litellm_logging.py:3482 - Error creating standard logging object - __annotations__
Traceback (most recent call last):
  File "C:\Users\PC\AppData\Roaming\Python\Python312\site-packages\litellm\litellm_core_utils\litellm_logging.py", line 3464, in get_standard_logging_object_payload
    model_parameters=ModelParamHelper.get_standard_logging_model_parameters(
                     ^^^^^^^^^^^^^^^^^^^^^^^^^^^^^^^^^^^^^^^^^^^^^^^^^^^^^^^
  File "C:\Users\PC\AppData\Roaming\Python\Python312\site-packages\litellm\litellm_core_utils\model_param_helper.py", line 28, in get_standard_logging_model_parameters
    ModelParamHelper._get_relevant_args_to_use_for_logging()
  File "C:\Users\PC\AppData\Roaming\Python\Python312\site-packages\litellm\litellm_core_utils\model_param_helper.py", line 45, in _get_relevant_args_to_use_for_logging
    all_openai_llm_api_params = ModelParamHelper._get_all_llm_api_params()
                                ^^^^^^^^^^^^^^^^^^^^^^^^^^^^^^^^^^^^^^^^^^
  File "C:\Users\PC\AppData\Roaming\Python\Python312\site-packages\litellm\litellm_core_utils\model_param_helper.py", line 65, in _get_all_llm_api_params
    ModelParamHelper._get_litellm_supported_transcription_kwargs()
  File "C:\Users\PC\AppData\Roaming\Python\Python312\site-packages\litellm\litellm_core_utils\model_param_helper.py", line 126, in _get_litellm_supported_transcription_kwargs
    return set(TranscriptionCreateParams.__annotations__.keys())
               ^^^^^^^^^^^^^^^^^^^^^^^^^^^^^^^^^^^^^^^^^
  File "C:\Python312\Lib\typing.py", line 1213, in __getattr__
    raise AttributeError(attr)
AttributeError: __annotations__
[92m20:41:43 - LiteLLM:ERROR[0m: caching.py:563 - LiteLLM Cache: Excepton add_cache: __annotations__
Traceback (most recent call last):
  File "C:\Users\PC\AppData\Roaming\Python\Python312\site-packages\dspy\adapters\chat_adapter.py", line 111, in parse
    fields[k] = parse_value(v, signature.output_fields[k].annotation)
                ^^^^^^^^^^^^^^^^^^^^^^^^^^^^^^^^^^^^^^^^^^^^^^^^^^^^^
  File "C:\Users\PC\AppData\Roaming\Python\Python312\site-packages\dspy\adapters\utils.py", line 106, in parse_value
    return TypeAdapter(annotation).validate_python(candidate)
           ^^^^^^^^^^^^^^^^^^^^^^^^^^^^^^^^^^^^^^^^^^^^^^^^^^
  File "C:\Users\PC\AppData\Roaming\Python\Python312\site-packages\pydantic\type_adapter.py", line 135, in wrapped
    return func(self, *args, **kwargs)
           ^^^^^^^^^^^^^^^^^^^^^^^^^^^
  File "C:\Users\PC\AppData\Roaming\Python\Python312\site-packages\pydantic\type_adapter.py", line 366, in validate_python
    return self.validator.validate_python(object, strict=strict, from_attributes=from_attributes, context=context)
           ^^^^^^^^^^^^^^^^^^^^^^^^^^^^^^^^^^^^^^^^^^^^^^^^^^^^^^^^^^^^^^^^^^^^^^^^^^^^^^^^^^^^^^^^^^^^^^^^^^^^^^^
pydantic_core._pydantic_core.ValidationError: 10 validation errors for list[str]
0
  Input should be a valid string [type=string_type, input_value={'input': 'abc', 'expected': 'YES'}, input_type=dict]
    For further information visit https://errors.pydantic.dev/2.9/v/string_type
1
  Input should be a valid string [type=string_type, input_value={'input': 'acb', 'expected': 'YES'}, input_type=dict]
    For further information visit https://errors.pydantic.dev/2.9/v/string_type
2
  Input should be a valid string [type=string_type, input_value={'input': 'bac', 'expected': 'YES'}, input_type=dict]
    For further information visit https://errors.pydantic.dev/2.9/v/string_type
3
  Input should be a valid string [type=string_type, input_value={'input': 'bca', 'expected': 'NO'}, input_type=dict]
    For further information visit https://errors.pydantic.dev/2.9/v/string_type
4
  Input should be a valid string [type=string_type, input_value={'input': 'cab', 'expected': 'NO'}, input_type=dict]
    For further information visit https://errors.pydantic.dev/2.9/v/string_type
5
  Input should be a valid string [type=string_type, input_value={'input': 'cba', 'expected': 'YES'}, input_type=dict]
    For further information visit https://errors.pydantic.dev/2.9/v/string_type
6
  Input should be a valid string [type=string_type, input_value={'input': 'abc', 'expected': 'YES'}, input_type=dict]
    For further information visit https://errors.pydantic.dev/2.9/v/string_type
7
  Input should be a valid string [type=string_type, input_value={'input': 'bac', 'expected': 'YES'}, input_type=dict]
    For further information visit https://errors.pydantic.dev/2.9/v/string_type
8
  Input should be a valid string [type=string_type, input_value={'input': 'acb', 'expected': 'YES'}, input_type=dict]
    For further information visit https://errors.pydantic.dev/2.9/v/string_type
9
  Input should be a valid string [type=string_type, input_value={'input': 'cba', 'expected': 'YES'}, input_type=dict]
    For further information visit https://errors.pydantic.dev/2.9/v/string_type

During handling of the above exception, another exception occurred:

Traceback (most recent call last):
  File "C:\Users\PC\AppData\Roaming\Python\Python312\site-packages\dspy\adapters\chat_adapter.py", line 49, in __call__
    return super().__call__(lm, lm_kwargs, signature, demos, inputs)
           ^^^^^^^^^^^^^^^^^^^^^^^^^^^^^^^^^^^^^^^^^^^^^^^^^^^^^^^^^
  File "C:\Users\PC\AppData\Roaming\Python\Python312\site-packages\dspy\adapters\base.py", line 43, in __call__
    value = self.parse(signature, output)
            ^^^^^^^^^^^^^^^^^^^^^^^^^^^^^
  File "C:\Users\PC\AppData\Roaming\Python\Python312\site-packages\dspy\utils\callback.py", line 266, in wrapper
    return fn(instance, *args, **kwargs)
           ^^^^^^^^^^^^^^^^^^^^^^^^^^^^^
  File "C:\Users\PC\AppData\Roaming\Python\Python312\site-packages\dspy\adapters\chat_adapter.py", line 113, in parse
    raise ValueError(
ValueError: Error parsing field test_cases: 10 validation errors for list[str]
0
  Input should be a valid string [type=string_type, input_value={'input': 'abc', 'expected': 'YES'}, input_type=dict]
    For further information visit https://errors.pydantic.dev/2.9/v/string_type
1
  Input should be a valid string [type=string_type, input_value={'input': 'acb', 'expected': 'YES'}, input_type=dict]
    For further information visit https://errors.pydantic.dev/2.9/v/string_type
2
  Input should be a valid string [type=string_type, input_value={'input': 'bac', 'expected': 'YES'}, input_type=dict]
    For further information visit https://errors.pydantic.dev/2.9/v/string_type
3
  Input should be a valid string [type=string_type, input_value={'input': 'bca', 'expected': 'NO'}, input_type=dict]
    For further information visit https://errors.pydantic.dev/2.9/v/string_type
4
  Input should be a valid string [type=string_type, input_value={'input': 'cab', 'expected': 'NO'}, input_type=dict]
    For further information visit https://errors.pydantic.dev/2.9/v/string_type
5
  Input should be a valid string [type=string_type, input_value={'input': 'cba', 'expected': 'YES'}, input_type=dict]
    For further information visit https://errors.pydantic.dev/2.9/v/string_type
6
  Input should be a valid string [type=string_type, input_value={'input': 'abc', 'expected': 'YES'}, input_type=dict]
    For further information visit https://errors.pydantic.dev/2.9/v/string_type
7
  Input should be a valid string [type=string_type, input_value={'input': 'bac', 'expected': 'YES'}, input_type=dict]
    For further information visit https://errors.pydantic.dev/2.9/v/string_type
8
  Input should be a valid string [type=string_type, input_value={'input': 'acb', 'expected': 'YES'}, input_type=dict]
    For further information visit https://errors.pydantic.dev/2.9/v/string_type
9
  Input should be a valid string [type=string_type, input_value={'input': 'cba', 'expected': 'YES'}, input_type=dict]
    For further information visit https://errors.pydantic.dev/2.9/v/string_type.

		On attempting to parse the value
```
[
    {"input": "abc", "expected": "YES"},
    {"input": "acb", "expected": "YES"},
    {"input": "bac", "expected": "YES"},
    {"input": "bca", "expected": "NO"},
    {"input": "cab", "expected": "NO"},
    {"input": "cba", "expected": "YES"},
    {"input": "abc", "expected": "YES"},
    {"input": "bac", "expected": "YES"},
    {"input": "acb", "expected": "YES"},
    {"input": "cba", "expected": "YES"}
]
```

During handling of the above exception, another exception occurred:

Traceback (most recent call last):
  File "C:\Users\PC\AppData\Roaming\Python\Python312\site-packages\litellm\caching\caching.py", line 558, in add_cache
    cache_key, cached_data, kwargs = self._add_cache_logic(
                                     ^^^^^^^^^^^^^^^^^^^^^^
  File "C:\Users\PC\AppData\Roaming\Python\Python312\site-packages\litellm\caching\caching.py", line 542, in _add_cache_logic
    raise e
  File "C:\Users\PC\AppData\Roaming\Python\Python312\site-packages\litellm\caching\caching.py", line 522, in _add_cache_logic
    cache_key = self.get_cache_key(**kwargs)
                ^^^^^^^^^^^^^^^^^^^^^^^^^^^^
  File "C:\Users\PC\AppData\Roaming\Python\Python312\site-packages\litellm\caching\caching.py", line 248, in get_cache_key
    combined_kwargs = ModelParamHelper._get_all_llm_api_params()
                      ^^^^^^^^^^^^^^^^^^^^^^^^^^^^^^^^^^^^^^^^^^
  File "C:\Users\PC\AppData\Roaming\Python\Python312\site-packages\litellm\litellm_core_utils\model_param_helper.py", line 65, in _get_all_llm_api_params
    ModelParamHelper._get_litellm_supported_transcription_kwargs()
  File "C:\Users\PC\AppData\Roaming\Python\Python312\site-packages\litellm\litellm_core_utils\model_param_helper.py", line 126, in _get_litellm_supported_transcription_kwargs
    return set(TranscriptionCreateParams.__annotations__.keys())
               ^^^^^^^^^^^^^^^^^^^^^^^^^^^^^^^^^^^^^^^^^
  File "C:\Python312\Lib\typing.py", line 1213, in __getattr__
    raise AttributeError(attr)
AttributeError: __annotations__
[92m20:41:43 - LiteLLM:ERROR[0m: litellm_logging.py:3482 - Error creating standard logging object - __annotations__
Traceback (most recent call last):
  File "C:\Users\PC\AppData\Roaming\Python\Python312\site-packages\litellm\litellm_core_utils\litellm_logging.py", line 3464, in get_standard_logging_object_payload
    model_parameters=ModelParamHelper.get_standard_logging_model_parameters(
                     ^^^^^^^^^^^^^^^^^^^^^^^^^^^^^^^^^^^^^^^^^^^^^^^^^^^^^^^
  File "C:\Users\PC\AppData\Roaming\Python\Python312\site-packages\litellm\litellm_core_utils\model_param_helper.py", line 28, in get_standard_logging_model_parameters
    ModelParamHelper._get_relevant_args_to_use_for_logging()
  File "C:\Users\PC\AppData\Roaming\Python\Python312\site-packages\litellm\litellm_core_utils\model_param_helper.py", line 45, in _get_relevant_args_to_use_for_logging
    all_openai_llm_api_params = ModelParamHelper._get_all_llm_api_params()
                                ^^^^^^^^^^^^^^^^^^^^^^^^^^^^^^^^^^^^^^^^^^
  File "C:\Users\PC\AppData\Roaming\Python\Python312\site-packages\litellm\litellm_core_utils\model_param_helper.py", line 65, in _get_all_llm_api_params
    ModelParamHelper._get_litellm_supported_transcription_kwargs()
  File "C:\Users\PC\AppData\Roaming\Python\Python312\site-packages\litellm\litellm_core_utils\model_param_helper.py", line 126, in _get_litellm_supported_transcription_kwargs
    return set(TranscriptionCreateParams.__annotations__.keys())
               ^^^^^^^^^^^^^^^^^^^^^^^^^^^^^^^^^^^^^^^^^
  File "C:\Python312\Lib\typing.py", line 1213, in __getattr__
    raise AttributeError(attr)
AttributeError: __annotations__
[92m20:41:43 - LiteLLM:ERROR[0m: litellm_logging.py:3482 - Error creating standard logging object - __annotations__
Traceback (most recent call last):
  File "C:\Users\PC\AppData\Roaming\Python\Python312\site-packages\litellm\litellm_core_utils\litellm_logging.py", line 3464, in get_standard_logging_object_payload
    model_parameters=ModelParamHelper.get_standard_logging_model_parameters(
                     ^^^^^^^^^^^^^^^^^^^^^^^^^^^^^^^^^^^^^^^^^^^^^^^^^^^^^^^
  File "C:\Users\PC\AppData\Roaming\Python\Python312\site-packages\litellm\litellm_core_utils\model_param_helper.py", line 28, in get_standard_logging_model_parameters
    ModelParamHelper._get_relevant_args_to_use_for_logging()
  File "C:\Users\PC\AppData\Roaming\Python\Python312\site-packages\litellm\litellm_core_utils\model_param_helper.py", line 45, in _get_relevant_args_to_use_for_logging
    all_openai_llm_api_params = ModelParamHelper._get_all_llm_api_params()
                                ^^^^^^^^^^^^^^^^^^^^^^^^^^^^^^^^^^^^^^^^^^
  File "C:\Users\PC\AppData\Roaming\Python\Python312\site-packages\litellm\litellm_core_utils\model_param_helper.py", line 65, in _get_all_llm_api_params
    ModelParamHelper._get_litellm_supported_transcription_kwargs()
  File "C:\Users\PC\AppData\Roaming\Python\Python312\site-packages\litellm\litellm_core_utils\model_param_helper.py", line 126, in _get_litellm_supported_transcription_kwargs
    return set(TranscriptionCreateParams.__annotations__.keys())
               ^^^^^^^^^^^^^^^^^^^^^^^^^^^^^^^^^^^^^^^^^
  File "C:\Python312\Lib\typing.py", line 1213, in __getattr__
    raise AttributeError(attr)
AttributeError: __annotations__
